Workbook

Sheet Portfolio Summary
A1: Portfolio Summary — Performance & Risk
A2: All figures are live formulas over Trade Log & Equity Curve. Gross unless labelled "after costs".
A4: OVERVIEW
A5: Backtest start | B5: ='Equity Curve'!A2 -> 39342
A6: Backtest end | B6: ='Equity Curve'!A4503 -> 46022
A7: Trading days | B7: =COUNT('Equity Curve'!$F$2:$F$4503) -> 4502
A8: Years | B8: =('Equity Curve'!A4503-'Equity Curve'!A2)/365.25 -> 18.288843
A9: Total trades | B9: =COUNT('Trade Log'!$L$2:$L$1468) -> 1467
A10: Long trades | B10: =COUNTIF('Trade Log'!$B$2:$B$1468,"Long") -> 746
A11: Short trades | B11: =COUNTIF('Trade Log'!$B$2:$B$1468,"Short") -> 721
A12: Same-day flips | B12: =COUNTIF('Trade Log'!$V$2:$V$1468,"Yes") -> 661
A13: Market exposure | B13: =COUNTIF('Equity Curve'!$B$2:$B$4503,"<>0")/COUNT('Equity Curve'!$F$2:$F$4503) -> 0.95313194
A14: Avg days held | B14: =AVERAGE('Trade Log'!$I$2:$I$1468) -> 2.3755965
A15: Max days held | B15: =MAX('Trade Log'!$I$2:$I$1468) -> 12
A17: RETURNS — GROSS (1 unit of index, mark-to-market)
A18: Net P&L (points) | B18: =SUM('Trade Log'!$L$2:$L$1468) -> 59528.75
A19: Equity multiple | B19: ='Equity Curve'!$G$4503 -> 49.1559
A20: CAGR | B20: ='Equity Curve'!$G$4503^(252/COUNT('Equity Curve'!$F$2:$F$4503))-1 -> 0.24361558
A21: Expectancy / trade (pts) | B21: =AVERAGE('Trade Log'!$L$2:$L$1468) -> 40.578562
A22: Avg trade return % | B22: =AVERAGE('Trade Log'!$M$2:$M$1468) -> 0.0030491235
A24: TRADE STATISTICS — GROSS
A25: Win rate | B25: =COUNTIF('Trade Log'!$L$2:$L$1468,">0")/COUNT('Trade Log'!$L$2:$L$1468) -> 0.40490798
A26: Winning trades | B26: =COUNTIF('Trade Log'!$L$2:$L$1468,">0") -> 594
A27: Losing trades | B27: =COUNTIF('Trade Log'!$L$2:$L$1468,"<0") -> 870
A28: Gross profit (pts) | B28: =SUMIF('Trade Log'!$L$2:$L$1468,">0") -> 270678.8
A29: Gross loss (pts) | B29: =SUMIF('Trade Log'!$L$2:$L$1468,"<0") -> -211150.05
A30: Profit factor | B30: =SUMIF('Trade Log'!$L$2:$L$1468,">0")/-SUMIF('Trade Log'!$L$2:$L$1468,"<0") -> 1.2819263
A31: Average win (pts) | B31: =AVERAGEIF('Trade Log'!$L$2:$L$1468,">0") -> 455.68822
A32: Average loss (pts) | B32: =AVERAGEIF('Trade Log'!$L$2:$L$1468,"<0") -> -242.70121
A33: Win/Loss ratio | B33: =AVERAGEIF('Trade Log'!$L$2:$L$1468,">0")/-AVERAGEIF('Trade Log'!$L$2:$L$1468,"<0") -> 1.8775688
A34: Largest win (pts) | B34: =MAX('Trade Log'!$L$2:$L$1468) -> 4760.3
A35: Largest loss (pts) | B35: =MIN('Trade Log'!$L$2:$L$1468) -> -2375.5
A36: Max consecutive wins | B36: =MAX('Trade Log'!$T$2:$T$1468) -> 6
A37: Max consecutive losses | B37: =MAX('Trade Log'!$U$2:$U$1468) -> 9
A39: RISK & RATIOS
A40: Sharpe (annualised) | B40: =AVERAGE('Equity Curve'!$F$2:$F$4503)/STDEV('Equity Curve'!$F$2:$F$4503)*SQRT(252) -> 1.0300492
A41: Sortino (annualised) | B41: =AVERAGE('Equity Curve'!$F$2:$F$4503)/SQRT(SUM('Equity Curve'!$J$2:$J$4503)/COUNT('Equity Curve'!$F$2:$F$4503))*SQRT(252) -> 1.6459648
A42: Volatility (annualised) | B42: =STDEV('Equity Curve'!$F$2:$F$4503)*SQRT(252) -> 0.23932117
A43: Max drawdown (%) | B43: =MIN('Equity Curve'!$I$2:$I$4503) -> -0.33717625
A44: Max drawdown (pts) | B44: =MIN('Equity Curve'!$L$2:$L$4503) -> -11562.35
...

Sheet Assumptions
A1: BANKNIFTY — Prev-2-Day Breakout, Trailing Prev-Day Stop, Same-Day Flip
A2: Daily backtest • 17-Sep-2007 to 31-Dec-2025 • Source: "Daily" sheet
A4: STRATEGY RULES
A5: Long entry | B5: Price breaks ABOVE the higher of the previous 2 days' highs
A6: Long entry fill | B6: At the breakout level (buy-stop); gap-up opens fill at the open
A7: Long stop-loss | B7: Previous day's LOW — FIXED at entry (disaster stop)
A8: Long target / exit | B8: Trailing stop at the PREVIOUS DAY'S LOW: exit when a day trades below the prior day's low, filled at that level
A9: Short entry | B9: Price breaks BELOW the lower of the previous 2 days' lows
A10: Short entry fill | B10: At the breakdown level (sell-stop); gap-down opens fill at the open
A11: Short stop-loss | B11: Previous day's HIGH — FIXED at entry (disaster stop)
A12: Short target / exit | B12: Trailing stop at the PREVIOUS DAY'S HIGH (mirror): exit when a day trades above the prior day's high, filled at that level
A14: POSITION / EXECUTION
A15: Position model | B15: ONE position at a time — long OR short, never overlapping
A16: Same-day flip | B16: On the exit day, if the OPPOSITE breakout also triggers, square off and immediately enter the opposite side (stop-and-reverse). Marked "Flip?" = Yes in the log.
A17: Exit evaluation | B17: Begins the day AFTER entry (min hold = 1 day)
A18: First entry tiebreak | B18: From flat, if long & short both trigger same day, side chosen by that day's close direction
A19: Gap handling | B19: If the open is already beyond the trigger level, fill at the open
A20: MFE / MAE | B20: Max favourable / adverse excursion over post-entry holding days, in points
A21: Metrics basis | B21: Points + daily mark-to-market % returns on 1 unit of index (capital-agnostic)
A23: COST MODEL (editable input)
A24: Cost rate (% of turnover) | B24: 0.0015 | C24: Rs 15,000 per Rs 1 crore turnover (round-trip). Edit B24 to re-test.

Sheet Trade Log
A1: # | B1: Direction | C1: Entry Date | D1: Exit Date | E1: Entry Price | F1: Stop Level | G1: Exit Price | H1: Exit Reason | I1: Days Held | J1: MFE (pts) | K1: MAE (pts) | L1: Gross P&L (pts) | M1: P&L % | N1: Turnover | O1: Cost (pts) | P1: Net P&L (pts) | Q1: Cum Gross | R1: Cum Net | S1: Win | T1: WinStk | U1: LossStk | V1: Flip?
A2: 1 | B2: Long | C2: 39344 | D2: 39350 | E2: 7111 | F2: 6883.6 | G2: 7514.4 | H2: Reversal | I2: 4 | J2: 583.2 | K2: 0 | L2: =IF(B2="Long",G2-E2,E2-G2) -> 403.4 | M2: =L2/E2 -> 0.056729011 | N2: =E2+G2 -> 14625.4 | O2: =N2*Assumptions!$B$24 -> 21.9381 | P2: =L2-O2 -> 381.4619 | Q2: =L2 -> 403.4 | R2: =P2 -> 381.4619 | S2: =IF(L2>0,1,0) -> 1 | T2: =IF(S2=1,1,0) -> 1 | U2: =IF(S2=0,1,0) -> 0
A3: 2 | B3: Long | C3: 39351 | D3: 39358 | E3: 7694.25 | F3: 7490.2 | G3: 7913.3 | H3: Reversal | I3: 4 | J3: 541.5 | K3: 0 | L3: =IF(B3="Long",G3-E3,E3-G3) -> 219.05 | M3: =L3/E3 -> 0.028469311 | N3: =E3+G3 -> 15607.55 | O3: =N3*Assumptions!$B$24 -> 23.411325 | P3: =L3-O3 -> 195.63868 | Q3: =Q2+L3 -> 622.45 | R3: =R2+P3 -> 577.10058 | S3: =IF(L3>0,1,0) -> 1 | T3: =IF(S3=1,T2+1,0) -> 2 | U3: =IF(S3=0,U2+1,0) -> 0 | V3: =IF(C3=D2,"Yes","")
A4: 3 | B4: Short | C4: 39358 | D4: 39359 | E4: 7836.05 | F4: 8085.15 | G4: 8085.15 | H4: Stop | I4: 1 | J4: 7.4 | K4: 250.6 | L4: =IF(B4="Long",G4-E4,E4-G4) -> -249.1 | M4: =L4/E4 -> -0.031788975 | N4: =E4+G4 -> 15921.2 | O4: =N4*Assumptions!$B$24 -> 23.8818 | P4: =L4-O4 -> -272.9818 | Q4: =Q3+L4 -> 373.35 | R4: =R3+P4 -> 304.11878 | S4: =IF(L4>0,1,0) -> 0 | T4: =IF(S4=1,T3+1,0) -> 0 | U4: =IF(S4=0,U3+1,0) -> 1 | V4: =IF(C4=D3,"Yes","") -> Yes
A5: 4 | B5: Short | C5: 39360 | D5: 39365 | E5: 7820.25 | F5: 8086.7 | G5: 7960.65 | H5: Reversal | I5: 3 | J5: 303.8 | K5: 260.8 | L5: =IF(B5="Long",G5-E5,E5-G5) -> -140.4 | M5: =L5/E5 -> -0.01795339 | N5: =E5+G5 -> 15780.9 | O5: =N5*Assumptions!$B$24 -> 23.67135 | P5: =L5-O5 -> -164.07135 | Q5: =Q4+L5 -> 232.95 | R5: =R4+P5 -> 140.04743 | S5: =IF(L5>0,1,0) -> 0 | T5: =IF(S5=1,T4+1,0) -> 0 | U5: =IF(S5=0,U4+1,0) -> 2 | V5: =IF(C5=D4,"Yes","")
A6: 5 | B6: Long | C6: 39365 | D6: 39367 | E6: 7960.65 | F6: 7535.05 | G6: 8005.5 | H6: Reversal | I6: 2 | J6: 217.1 | K6: 70.8 | L6: =IF(B6="Long",G6-E6,E6-G6) -> 44.85 | M6: =L6/E6 -> 0.0056339621 | N6: =E6+G6 -> 15966.15 | O6: =N6*Assumptions!$B$24 -> 23.949225 | P6: =L6-O6 -> 20.900775 | Q6: =Q5+L6 -> 277.8 | R6: =R5+P6 -> 160.9482 | S6: =IF(L6>0,1,0) -> 1 | T6: =IF(S6=1,T5+1,0) -> 1 | U6: =IF(S6=0,U5+1,0) -> 0 | V6: =IF(C6=D5,"Yes","") -> Yes
A7: 6 | B7: Short | C7: 39367 | D7: 39370 | E7: 7907.35 | F7: 8177.75 | G7: 8132.1 | H7: Reversal | I7: 1 | J7: 0 | K7: 399 | L7: =IF(B7="Long",G7-E7,E7-G7) -> -224.75 | M7: =L7/E7 -> -0.028422923 | N7: =E7+G7 -> 16039.45 | O7: =N7*Assumptions!$B$24 -> 24.059175 | P7: =L7-O7 -> -248.80918 | Q7: =Q6+L7 -> 53.05 | R7: =R6+P7 -> -87.860975 | S7: =IF(L7>0,1,0) -> 0 | T7: =IF(S7=1,T6+1,0) -> 0 | U7: =IF(S7=0,U6+1,0) -> 1 | V7: =IF(C7=D6,"Yes","") -> Yes
A8: 7 | B8: Long | C8: 39370 | D8: 39372 | E8: 8177.75 | F8: 7889.8 | G8: 8071.55 | H8: Reversal | I8: 2 | J8: 313.9 | K8: 536.2 | L8: =IF(B8="Long",G8-E8,E8-G8) -> -106.2 | M8: =L8/E8 -> -0.012986457 | N8: =E8+G8 -> 16249.3 | O8: =N8*Assumptions!$B$24 -> 24.37395 | P8: =L8-O8 -> -130.57395 | Q8: =Q7+L8 -> -53.15 | R8: =R7+P8 -> -218.43492 | S8: =IF(L8>0,1,0) -> 0 | T8: =IF(S8=1,T7+1,0) -> 0 | U8: =IF(S8=0,U7+1,0) -> 2 | V8: =IF(C8=D7,"Yes","") -> Yes
A9: 8 | B9: Short | C9: 39372 | D9: 39378 | E9: 7962.55 | F9: 8491.65 | G9: 7621.65 | H9: Reversal | I9: 4 | J9: 683.2 | K9: 229.9 | L9: =IF(B9="Long",G9-E9,E9-G9) -> 340.9 | M9: =L9/E9 -> 0.042812918 | N9: =E9+G9 -> 15584.2 | O9: =N9*Assumptions!$B$24 -> 23.3763 | P9: =L9-O9 -> 317.5237 | Q9: =Q8+L9 -> 287.75 | R9: =R8+P9 -> 99.088775 | S9: =IF(L9>0,1,0) -> 1 | T9: =IF(S9=1,T8+1,0) -> 1 | U9: =IF(S9=0,U8+1,0) -> 0 | V9: =IF(C9=D8,"Yes","") -> Yes
A10: 9 | B10: Long | C10: 39378 | D10: 39385 | E10: 7718.9 | F10: 7289.2 | G10: 8865.65 | H10: Reversal | I10: 5 | J10: 1518.9 | K10: 0 | L10: =IF(B10="Long",G10-E10,E10-G10) -> 1146.75 | M10: =L10/E10 -> 0.14856391 | N10: =E10+G10 -> 16584.55 | O10: =N10*Assumptions!$B$24 -> 24.876825 | P10: =L10-O10 -> 1121.8732 | Q10: =Q9+L10 -> 1434.5 | R10: =R9+P10 -> 1220.9619 | S10: =IF(L10>0,1,0) -> 1 | T10: =IF(S10=1,T9+1,0) -> 2 | U10: =IF(S10=0,U9+1,0) -> 0 | V10: =IF(C10=D9,"Yes","") -> Yes
A11: 10 | B11: Long | C11: 39387 | D11: 39388 | E11: 9237.8 | F11: 8839.4 | G11: 8953.4 | H11: Reversal | I11: 1 | J11: 372.9 | K11: 339.6 | L11: =IF(B11="Long",G11-E11,E11-G11) -> -284.4 | M11: =L11/E11 -> -0.030786551 | N11: =E11+G11 -> 18191.2 | O11: =N11*Assumptions!$B$24 -> 27.2868 | P11: =L11-O11 -> -311.6868 | Q11: =Q10+L11 -> 1150.1 | R11: =R10+P11 -> 909.27515 | S11: =IF(L11>0,1,0) -> 0 | T11: =IF(S11=1,T10+1,0) -> 0 | U11: =IF(S11=0,U10+1,0) -> 1 | V11: =IF(C11=D10,"Yes","")
A12: 11 | B12: Long | C12: 39391 | D12: 39392 | E12: 9610.7 | F12: 8898.2 | G12: 9346.25 | H12: Reversal | I12: 1 | J12: 0 | K12: 480.9 | L12: =IF(B12="Long",G12-E12,E12-G12) -> -264.45 | M12: =L12/E12 -> -0.027516206 | N12: =E12+G12 -> 18956.95 | O12: =N12*Assumptions!$B$24 -> 28.435425 | P12: =L12-O12 -> -292.88543 | Q12: =Q11+L12 -> 885.65 | R12: =R11+P12 -> 616.38973 | S12: =IF(L12>0,1,0) -> 0 | T12: =IF(S12=1,T11+1,0) -> 0 | U12: =IF(S12=0,U11+1,0) -> 2 | V12: =IF(C12=D11,"Yes","")
A13: 12 | B13: Short | C13: 39393 | D13: 39399 | E13: 9129.85 | F13: 9550.65 | G13: 8819.9 | H13: Reversal | I13: 3 | J13: 700.5 | K13: 19.1 | L13: =IF(B13="Long",G13-E13,E13-G13) -> 309.95 | M13: =L13/E13 -> 0.033949079 | N13: =E13+G13 -> 17949.75 | O13: =N13*Assumptions!$B$24 -> 26.924625 | P13: =L13-O13 -> 283.02538 | Q13: =Q12+L13 -> 1195.6 | R13: =R12+P13 -> 899.4151 | S13: =IF(L13>0,1,0) -> 1 | T13: =IF(S13=1,T12+1,0) -> 1 | U13: =IF(S13=0,U12+1,0) -> 0 | V13: =IF(C13=D12,"Yes","")
A14: 13 | B14: Long | C14: 39399 | D14: 39402 | E14: 9090.8 | F14: 8429.35 | G14: 9422.35 | H14: Reversal | I14: 3 | J14: 561.1 | K14: 0 | L14: =IF(B14="Long",G14-E14,E14-G14) -> 331.55 | M14: =L14/E14 -> 0.036470938 | N14: =E14+G14 -> 18513.15 | O14: =N14*Assumptions!$B$24 -> 27.769725 | P14: =L14-O14 -> 303.78028 | Q14: =Q13+L14 -> 1527.15 | R14: =R13+P14 -> 1203.1954 | S14: =IF(L14>0,1,0) -> 1 | T14: =IF(S14=1,T13+1,0) -> 2 | U14: =IF(S14=0,U13+1,0) -> 0 | V14: =IF(C14=D13,"Yes","") -> Yes
... A1468: 1467 | B1468: Long | C1468: 46021 | D1468: 46022 | E1468: 59180.65 | F1468: 58809.55 | G1468: 59581.85 | H1468: Open(EOD) | I1468: 1 | J1468: 585.5 | K1468: 0 | L1468: =IF(B1468="Long",G1468-E1468,E1468-G1468) -> 401.2 | M1468: =L1468/E1468 -> 0.0067792429 | N1468: =E1468+G1468 -> 118762.5 | O1468: =N1468*Assumptions!$B$24 -> 178.14375 | P1468: =L1468-O1468 -> 223.05625 | Q1468: =Q1467+L1468 -> 59528.75 | R1468: =R1467+P1468 -> -45434.42 | S1468: =IF(L1468>0,1,0) -> 1 | T1468: =IF(S1468=1,T1467+1,0) -> 2 | U1468: =IF(S1468=0,U1467+1,0) -> 0 | V1468: =IF(C1468=D1467,"Yes","") -> Yes

Sheet Equity Curve
A1: Date | B1: Position | C1: Close | D1: Daily P&L (pts) | E1: Cum P&L (pts) | F1: Daily Return % | G1: Equity (x) | H1: Peak | I1: Drawdown % | J1: NegRet2 | K1: PeakPts | L1: DD (pts)
A2: 39342 | B2: 0 | C2: 6897.1 | D2: 0 | E2: =D2 -> 0 | F2: 0 | G2: 1 | H2: =G2 -> 1 | I2: 0 | J2: 0 | K2: =E2 -> 0 | L2: 0
A3: 39343 | B3: 0 | C3: 7059.65 | D3: 0 | E3: =E2+D3 -> 0 | F3: =IF(C2>0,D3/C2,0) -> 0 | G3: =G2*(1+F3) -> 1 | H3: =MAX(H2,G3) -> 1 | I3: =G3/H3-1 -> 0 | J3: =IF(F3<0,F3^2,0) -> 0 | K3: =MAX(K2,E3) -> 0 | L3: =E3-K3 -> 0
A4: 39344 | B4: 1 | C4: 7401.85 | D4: 290.85 | E4: =E3+D4 -> 290.85 | F4: =IF(C3>0,D4/C3,0) -> 0.041198926 | G4: =G3*(1+F4) -> 1.0411989 | H4: =MAX(H3,G4) -> 1.0411989 | I4: =G4/H4-1 -> 0 | J4: =IF(F4<0,F4^2,0) -> 0 | K4: =MAX(K3,E4) -> 290.85 | L4: =E4-K4 -> 0
A5: 39345 | B5: 1 | C5: 7390.15 | D5: -11.7 | E5: =E4+D5 -> 279.15 | F5: =IF(C4>0,D5/C4,0) -> -0.0015806859 | G5: =G4*(1+F5) -> 1.0395531 | H5: =MAX(H4,G5) -> 1.0411989 | I5: =G5/H5-1 -> -0.0015806859 | J5: =IF(F5<0,F5^2,0) -> 2.4985679e-06 | K5: =MAX(K4,E5) -> 290.85 | L5: =E5-K5 -> -11.7
A6: 39346 | B6: 1 | C6: 7464.5 | D6: 74.35 | E6: =E5+D6 -> 353.5 | F6: =IF(C5>0,D6/C5,0) -> 0.010060689 | G6: =G5*(1+F6) -> 1.0500117 | H6: =MAX(H5,G6) -> 1.0500117 | I6: =G6/H6-1 -> 0 | J6: =IF(F6<0,F6^2,0) -> 0 | K6: =MAX(K5,E6) -> 353.5 | L6: =E6-K6 -> 0
A7: 39349 | B7: 1 | C7: 7650.9 | D7: 186.4 | E7: =E6+D7 -> 539.9 | F7: =IF(C6>0,D7/C6,0) -> 0.024971532 | G7: =G6*(1+F7) -> 1.0762321 | H7: =MAX(H6,G7) -> 1.0762321 | I7: =G7/H7-1 -> 0 | J7: =IF(F7<0,F7^2,0) -> 0 | K7: =MAX(K6,E7) -> 539.9 | L7: =E7-K7 -> 0
A8: 39350 | B8: 1 | C8: 7629.15 | D8: -136.5 | E8: =E7+D8 -> 403.4 | F8: =IF(C7>0,D8/C7,0) -> -0.017841038 | G8: =G7*(1+F8) -> 1.057031 | H8: =MAX(H7,G8) -> 1.0762321 | I8: =G8/H8-1 -> -0.017841038 | J8: =IF(F8<0,F8^2,0) -> 0.00031830265 | K8: =MAX(K7,E8) -> 539.9 | L8: =E8-K8 -> -136.5
A9: 39351 | B9: 1 | C9: 7755.9 | D9: 61.65 | E9: =E8+D9 -> 465.05 | F9: =IF(C8>0,D9/C8,0) -> 0.0080808478 | G9: =G8*(1+F9) -> 1.0655727 | H9: =MAX(H8,G9) -> 1.0762321 | I9: =G9/H9-1 -> -0.0099043612 | J9: =IF(F9<0,F9^2,0) -> 0 | K9: =MAX(K8,E9) -> 539.9 | L9: =E9-K9 -> -74.85
A10: 39352 | B10: 1 | C10: 7833.65 | D10: 77.75 | E10: =E9+D10 -> 542.8 | F10: =IF(C9>0,D10/C9,0) -> 0.010024626 | G10: =G9*(1+F10) -> 1.0762547 | H10: =MAX(H9,G10) -> 1.0762547 | I10: =G10/H10-1 -> 0 | J10: =IF(F10<0,F10^2,0) -> 0 | K10: =MAX(K9,E10) -> 542.8 | L10: =E10-K10 -> 0
A11: 39353 | B11: 1 | C11: 8042.2 | D11: 208.55 | E11: =E10+D11 -> 751.35 | F11: =IF(C10>0,D11/C10,0) -> 0.026622328 | G11: =G10*(1+F11) -> 1.1049071 | H11: =MAX(H10,G11) -> 1.1049071 | I11: =G11/H11-1 -> 0 | J11: =IF(F11<0,F11^2,0) -> 0 | K11: =MAX(K10,E11) -> 751.35 | L11: =E11-K11 -> 0
A12: 39356 | B12: 1 | C12: 7987.5 | D12: -54.7 | E12: =E11+D12 -> 696.65 | F12: =IF(C11>0,D12/C11,0) -> -0.0068016214 | G12: =G11*(1+F12) -> 1.097392 | H12: =MAX(H11,G12) -> 1.1049071 | I12: =G12/H12-1 -> -0.0068016214 | J12: =IF(F12<0,F12^2,0) -> 4.6262054e-05 | K12: =MAX(K11,E12) -> 751.35 | L12: =E12-K12 -> -54.7
A13: 39358 | B13: -1 | C13: 8097.9 | D13: -336.05 | E13: =E12+D13 -> 360.6 | F13: =IF(C12>0,D13/C12,0) -> -0.042071987 | G13: =G12*(1+F13) -> 1.0512225 | H13: =MAX(H12,G13) -> 1.1049071 | I13: =G13/H13-1 -> -0.048587451 | J13: =IF(F13<0,F13^2,0) -> 0.0017700521 | K13: =MAX(K12,E13) -> 751.35 | L13: =E13-K13 -> -390.75
A14: 39359 | B14: -1 | C14: 8035.9 | D14: 12.75 | E14: =E13+D14 -> 373.35 | F14: =IF(C13>0,D14/C13,0) -> 0.0015744823 | G14: =G13*(1+F14) -> 1.0528776 | H14: =MAX(H13,G14) -> 1.1049071 | I14: =G14/H14-1 -> -0.047089469 | J14: =IF(F14<0,F14^2,0) -> 0 | K14: =MAX(K13,E14) -> 751.35 | L14: =E14-K14 -> -378
... A4503: 46022 | B4503: 1 | C4503: 59581.85 | D4503: 410.6 | E4503: =E4502+D4503 -> 59528.75 | F4503: =IF(C4502>0,D4503/C4502,0) -> 0.0069391808 | G4503: =G4502*(1+F4503) -> 49.1559 | H4503: =MAX(H4502,G4503) -> 60.349268 | I4503: =G4503/H4503-1 -> -0.18547645 | J4503: =IF(F4503<0,F4503^2,0) -> 0 | K4503: =MAX(K4502,E4503) -> 64626.65 | L4503: =E4503-K4503 -> -5097.9
